<?xml version="1.0"?>
<robot name="ar4" xmlns:xacro="http://www.ros.org/wiki/xacro">
  <xacro:property name="package_name" value="ar4_description"/>

  <xacro:include filename="$(find ${package_name})/urdf/include/common_macros.urdf.xacro" />
  <xacro:property name="robot_properties_yaml_dir" value="$(find ${package_name})/config/link_properties.yaml" />
  <xacro:property name="robot_properties" value="${xacro.load_yaml(robot_properties_yaml_dir)}"/>
  <xacro:property name="robot_parameters_yaml_dir" value="$(find ${package_name})/config/ar4.yaml" />
  <xacro:property name="robot_parameters" value="${xacro.load_yaml(robot_parameters_yaml_dir)}"/>

  <xacro:link link_name="base_link"
              inertial="${robot_properties['base_link']['inertial']}"
              visual="${robot_properties['base_link']['visual']}"
              collision="${robot_properties['base_link']['collision']}"
              meshes="${['base_link', 'base_link_bottom', 'base_link_motor']}"
              materials="${['grey', 'blue', 'black']}">
              <origin xyz="0 0 0" rpy="0 0 0" />
  </xacro:link>
  <xacro:link link_name="link_1"
              inertial="${robot_properties['link_1']['inertial']}"
              visual="${robot_properties['link_1']['visual']}"
              collision="${robot_properties['link_1']['collision']}"
              meshes="${['link_1', 'link_1_motor']}"
              materials="${['grey', 'black']}">
    <origin xyz="0 0 0" rpy="0 0 0" />
  </xacro:link>
  <joint name="joint_1" type="revolute">
    <origin rpy="0 0 0" xyz="0 0 0"/>
    <parent link="base_link"/>
    <child link="link_1"/>
    <axis xyz="0 0 1"/>
    <limit lower="${-170.0 / 180.0 * pi}" upper="${170.0 / 180.0 * pi}" effort="100" velocity="0.5"/>
  </joint>

  <xacro:link link_name="link_2"
              inertial="${robot_properties['link_2']['inertial']}"
              visual="${robot_properties['link_2']['visual']}"
              collision="${robot_properties['link_2']['collision']}"
              meshes="${['link_2', 'link_2_motor', 'link_2_cover', 'link_2_cover_logo']}"
              materials="${['grey', 'black', 'white', 'blue']}">
    <origin xyz="0 0 0" rpy="0 0 0" />
  </xacro:link>
  <joint name="joint_2" type="revolute">
    <origin rpy="-1.5708 0 0" xyz="0.0642 0 0.16977"/>
    <parent link="link_1"/>
    <child link="link_2"/>
    <axis xyz="0 0 1"/>
    <limit lower="${-42.0 / 180.0 * pi}" upper="${90.0 / 180.0 * pi}" effort="100" velocity="0.5"/>
  </joint>

  <xacro:link link_name="link_3"
              inertial="${robot_properties['link_3']['inertial']}"
              visual="${robot_properties['link_3']['visual']}"
              collision="${robot_properties['link_3']['collision']}"
              meshes="${['link_3', 'link_3_motor', 'link_3_misc']}"
              materials="${['grey', 'black', 'black']}">
    <origin xyz="0 0 0" rpy="0 0 0" />
  </xacro:link>
  <joint name="joint_3" type="revolute">
    <origin rpy="0 0 -1.5708" xyz="0 -0.305 0"/>
    <parent link="link_2"/>
    <child link="link_3"/>
    <axis xyz="0 0 1"/>
    <limit lower="${-89.0 / 180.0 * pi}" upper="${52.0 / 180.0 * pi}" effort="100" velocity="0.5"/>
  </joint>

  <xacro:link link_name="link_4"
              inertial="${robot_properties['link_4']['inertial']}"
              visual="${robot_properties['link_4']['visual']}"
              collision="${robot_properties['link_4']['collision']}"
              meshes="${['link_4', 'link_4_motor']}"
              materials="${['grey', 'black']}">
    <origin xyz="0 0 0" rpy="0 0 0" />
  </xacro:link>
  <joint name="joint_4" type="revolute">
    <origin rpy="-1.5708 0 0" xyz="0 0 0.0"/>
    <parent link="link_3"/>
    <child link="link_4"/>
    <axis xyz="0 0 1"/>
    <limit lower="${-1 * robot_parameters['j4_limit']}" upper="${robot_parameters['j4_limit']}" effort="100" velocity="0.5"/>
  </joint>

  <xacro:link link_name="link_5"
              inertial="${robot_properties['link_5']['inertial']}"
              visual="${robot_properties['link_5']['visual']}"
              collision="${robot_properties['link_5']['collision']}"
              meshes="${['link_5', 'link_5_motor']}"
              materials="${['grey', 'black']}">
    <origin xyz="0 0 0" rpy="0 0 0" />
  </xacro:link>
  <joint name="joint_5" type="revolute">
    <origin rpy="1.5708 0 0" xyz="0 0 0.22263"/>
    <parent link="link_4"/>
    <child link="link_5"/>
    <axis xyz="0 0 1"/>
    <limit lower="${-105.0 / 180.0 * pi}" upper="${105.0 / 180.0 * pi}" effort="100" velocity="1.0"/>
  </joint>

  <xacro:link link_name="link_6"
              inertial="${robot_properties['link_6']['inertial']}"
              visual="${robot_properties['link_6']['visual']}"
              collision="${robot_properties['link_6']['collision']}"
              meshes="${['link_6']}"
              materials="${['grey']}">
    <origin xyz="0 0 0" rpy="0 0 0" />
  </xacro:link>
  <joint name="joint_6" type="revolute">
    <origin rpy="0 -1.5708 0" xyz="-${robot_parameters['l6_length']} 0 0"/>
    <parent link="link_5"/>
    <child link="link_6"/>
    <axis xyz="0 0 1"/>
    <limit lower="${-1.0 * robot_parameters['j6_limit']}" upper="${robot_parameters['j6_limit']}" effort="100" velocity="1.0"/>
  </joint>


  <!-- 夾爪 -->
  <joint name="gripper_joint" type="fixed">
    <origin rpy="0 0 0" xyz="0 0 0"/>
    <parent link="link_6"/>
    <child link="cylinder"/>
  </joint>
  <!-- Link cylinder -->
  <link name="cylinder">
    <inertial>
      <origin xyz="0 0 0" rpy="0 0 0"/>
      <mass value="0.01"/>
      <inertia ixx="0.0001" ixy="0" ixz="0" iyy="0.0001" iyz="0" izz="0.0001"/>
    </inertial>
    <!-- Part arm_holder -->
    <visual>
      <origin xyz="0 0 0.006" rpy="1.5708 0 -3.14159"/>
      <geometry>
        <mesh filename="file://$(find ar4_description)/meshes//arm_holder.stl"/>
      </geometry>
      <material name="arm_holder_material">
        <color rgba="0.980392 0.713725 0.00392157 1"/>
      </material>
    </visual>
    <collision>
      <origin xyz="0 0 0.006" rpy="1.5708 0 -3.14159"/>
      <geometry>
        <mesh filename="file://$(find ar4_description)/meshes/arm_holder.stl"/>
      </geometry>
    </collision>
    <!-- Part deep_camera -->
    <visual>
      <origin xyz="0 0.08157 0.039" rpy="-0 0 -3.14159"/>
      <geometry>
        <mesh filename="file://$(find ar4_description)/meshes/deep_camera.stl"/>
      </geometry>
      <material name="deep_camera_material">
        <color rgba="1 1 1 1"/>
      </material>
    </visual>
    <collision>
      <origin xyz="0 0.08157 0.039" rpy="-0 0 -3.14159"/>
      <geometry>
        <mesh filename="file://$(find ar4_description)/meshes/deep_camera.stl"/>
      </geometry>
    </collision>
    <!-- Part cylinder -->
    <visual>
      <origin xyz="0 0 0.006" rpy="1.5708 -0 -3.14159"/>
      <geometry>
        <mesh filename="file://$(find ar4_description)/meshes/cylinder.stl"/>
      </geometry>
      <material name="cylinder_material">
        <color rgba="0.647059 0.647059 0.647059 1"/>
      </material>
    </visual>
    <collision>
      <origin xyz="0 0 0.006" rpy="1.5708 -0 -3.14159"/>
      <geometry>
        <mesh filename="file://$(find ar4_description)/meshes/cylinder.stl"/>
      </geometry>
    </collision>
    <!-- Part deep_camera_holder -->
    <visual>
      <origin xyz="0 -0.0003 0.006" rpy="-1.5708 0 -3.14159"/>
      <geometry>
        <mesh filename="file://$(find ar4_description)/meshes/deep_camera_holder.stl"/>
      </geometry>
      <material name="deep_camera_holder_material">
        <color rgba="0.980392 0.713725 0.00392157 1"/>
      </material>
    </visual>
    <collision>
      <origin xyz="0 -0.0003 0.006" rpy="-1.5708 0 -3.14159"/>
      <geometry>
        <mesh filename="file://$(find ar4_description)/meshes/deep_camera_holder.stl"/>
      </geometry>
    </collision>
  </link>
  <!-- Frame camera (dummy link + fixed joint) -->
  <link name="camera">
    <origin xyz="0 0 0" rpy="0 -0 0"/>
    <inertial>
      <origin xyz="0 0 0" rpy="0 0 0"/>
      <mass value="0.01"/>
      <inertia ixx="0.0001" ixy="0" ixz="0" iyy="0.0001" iyz="0" izz="0.0001"/>
    </inertial>
  </link>
  <joint name="camera_frame" type="fixed">
    <origin xyz="0.0301 0.08157 0.036" rpy="-0 0 -3.14159"/>
    <parent link="cylinder"/>
    <child link="camera"/>
    <axis xyz="0 0 0"/>
  </joint>
  <!-- Frame depth_camera (dummy link + fixed joint) -->
  <link name="depth_camera">
    <origin xyz="0 0 0" rpy="0 -0 0"/>
    <inertial>
      <origin xyz="0 0 0" rpy="0 0 0"/>
      <mass value="0.01"/>
      <inertia ixx="0.0001" ixy="0" ixz="0" iyy="0.0001" iyz="0" izz="0.0001"/>
    </inertial>
  </link>
  <joint name="depth_camera_frame" type="fixed">
    <origin xyz="-0.0019 0.08157 0.036" rpy="1.570795 -1.570795 -3.14159"/>
    <parent link="cylinder"/>
    <child link="depth_camera"/>
    <axis xyz="0 0 0"/>
  </joint>
  <!-- Link gripper -->
  <link name="gripper">
    <inertial>
      <origin xyz="0 0 0" rpy="0 0 0"/>
      <mass value="0.01"/>
      <inertia ixx="0.001" ixy="0" ixz="0" iyy="0.001" iyz="0" izz="0.001"/>
    </inertial>
    <!-- Part gripper -->
    <visual>
      <origin xyz="-0.0495 -0.0249 0.003" rpy="-1.5708 -1.5708 0"/>
      <geometry>
        <mesh filename="file://$(find ar4_description)/meshes/gripper.stl"/>
      </geometry>
      <material name="gripper_material">
        <color rgba="0.980392 0.713725 0.00392157 1"/>
      </material>
    </visual>
    <collision>
      <origin xyz="-0.0495 -0.0249 0.003" rpy="-1.5708 -1.5708 0"/>
      <geometry>
        <mesh filename="file://$(find ar4_description)/meshes/gripper.stl"/>
      </geometry>
    </collision>
  </link>
  <!-- Joint from cylinder to gripper -->
  <joint name="grip_to_base1" type="revolute">
    <origin xyz="0.020064 -0.0150481 0.0545" rpy="1.5708 -1.0821 2.61799"/>
    <parent link="cylinder"/>
    <child link="gripper"/>
    <axis xyz="0 0 1"/>
    <limit effort="10" velocity="10" lower="-0.001" upper="0.488692"/>
  </joint>
  <!-- Link gripper_2 -->
  <link name="gripper_2">
    <inertial>
      <origin xyz="0 0 0" rpy="0 0 0"/>
      <mass value="0.01"/>
      <inertia ixx="0.001" ixy="0" ixz="0" iyy="0.001" iyz="0" izz="0.001"/>
    </inertial>
    <!-- Part gripper_2 -->
    <visual>
      <origin xyz="-0.0495 -0.0249 0.003" rpy="-1.5708 -1.5708 0"/>
      <geometry>
        <mesh filename="file://$(find ar4_description)/meshes/gripper.stl"/>
      </geometry>
      <material name="gripper_2_material">
        <color rgba="0.980392 0.713725 0.00392157 1"/>
      </material>
    </visual>
    <collision>
      <origin xyz="-0.0495 -0.0249 0.003" rpy="-1.5708 -1.5708 0"/>
      <geometry>
        <mesh filename="file://$(find ar4_description)/meshes/gripper.stl"/>
      </geometry>
    </collision>
  </link>
  <!-- Joint from cylinder to gripper_2 -->
  <joint name="grip_to_base2" type="revolute">
    <origin xyz="-0.023064 -0.00985192 0.0545" rpy="1.5708 -1.0821 0.523599"/>
    <parent link="cylinder"/>
    <child link="gripper_2"/>
    <axis xyz="0 0 1"/>
    <limit effort="10" velocity="10" lower="-0.001" upper="0.488692"/>
    <mimic joint="grip_to_base1" multiplier="1.0"/>
  </joint>
  <!-- Link gripper_3 -->
  <link name="gripper_3">
    <inertial>
      <origin xyz="0 0 0" rpy="0 0 0"/>
      <mass value="0.01"/>
      <inertia ixx="0.001" ixy="0" ixz="0" iyy="0.001" iyz="0" izz="0.001"/>
    </inertial>
    <!-- Part gripper_3 -->
    <visual>
      <origin xyz="-0.0495 -0.0249 0.003" rpy="-1.5708 -1.5708 0"/>
      <geometry>
        <mesh filename="file://$(find ar4_description)/meshes/gripper.stl"/>
      </geometry>
      <material name="gripper_3_material">
        <color rgba="0.980392 0.713725 0.00392157 1"/>
      </material>
    </visual>
    <collision>
      <origin xyz="-0.0495 -0.0249 0.003" rpy="-1.5708 -1.5708 0"/>
      <geometry>
        <mesh filename="file://$(find ar4_description)/meshes/gripper.stl"/>
      </geometry>
    </collision>
  </link>
  <!-- Joint from cylinder to gripper_3 -->
  <joint name="grip_to_base3" type="revolute">
    <origin xyz="0.003 0.0249 0.0545" rpy="1.5708 -1.0821 -1.5708"/>
    <parent link="cylinder"/>
    <child link="gripper_3"/>
    <axis xyz="0 0 1"/>
    <limit effort="10" velocity="10" lower="-0.001" upper="0.488692"/>
    <mimic joint="grip_to_base1" multiplier="1.0"/>
  </joint>

  <!-- Frame gripper_tcp (Tool Center Point) -->
  <link name="gripper_tcp"/>
  
  <joint name="gripper_tcp_joint" type="fixed">
    <!-- 這裡的 xyz 可以根據您夾爪末端的實際距離進行微調，目前 z 暫設為 0.1515 (15.15公分) -->
    <origin xyz="0 0 0.1515" rpy="0 0 0"/>
    <parent link="link_6"/>
    <child link="gripper_tcp"/>
  </joint>

</robot>
